[34m[1mwandb[0m: [32m[41mERROR[0m Expected `data_table` to be `wandb.Table` type, instead got DataFrame
Traceback (most recent call last):
  File "/gpfs/workdir/islamm/wandb_draw/wandb_visualization.py", line 11, in <module>
    chart_nmi = wandb.plot.line(df, x="Epoch", y="NMI Score", title="Training NMI")
                ^^^^^^^^^^^^^^^^^^^^^^^^^^^^^^^^^^^^^^^^^^^^^^^^^^^^^^^^^^^^^^^^^^^
  File "/gpfs/users/islamm/.local/lib/python3.12/site-packages/wandb/plot/line.py", line 68, in line
    return plot_table(
           ^^^^^^^^^^^
  File "/gpfs/users/islamm/.local/lib/python3.12/site-packages/wandb/plot/custom_chart.py", line 112, in plot_table
    raise wandb.Error(
wandb.errors.errors.Error: Expected `data_table` to be `wandb.Table` type, instead got DataFrame
