Traceback (most recent call last):
  File "/gpfs/users/islamm/.conda/envs/deepcluster/lib/python3.9/site-packages/pandas/core/indexes/base.py", line 3805, in get_loc
    return self._engine.get_loc(casted_key)
  File "index.pyx", line 167, in pandas._libs.index.IndexEngine.get_loc
  File "index.pyx", line 196, in pandas._libs.index.IndexEngine.get_loc
  File "pandas/_libs/hashtable_class_helper.pxi", line 7081, in pandas._libs.hashtable.PyObjectHashTable.get_item
  File "pandas/_libs/hashtable_class_helper.pxi", line 7089, in pandas._libs.hashtable.PyObjectHashTable.get_item
KeyError: 'AverageLosss'

The above exception was the direct cause of the following exception:

Traceback (most recent call last):
  File "/gpfs/workdir/islamm/wandb_draw/wandb_visualization_p4m.py", line 12, in <module>
    wandb.log({"Epoch": df["Epoch"][i], "NMI": df["NMIScore"][i], "AverageLoss": df["AverageLosss"][i]})
  File "/gpfs/users/islamm/.conda/envs/deepcluster/lib/python3.9/site-packages/pandas/core/frame.py", line 4102, in __getitem__
    indexer = self.columns.get_loc(key)
  File "/gpfs/users/islamm/.conda/envs/deepcluster/lib/python3.9/site-packages/pandas/core/indexes/base.py", line 3812, in get_loc
    raise KeyError(key) from err
KeyError: 'AverageLosss'
